Workbook

Sheet (검증1)이상치 검정
A1: 1. LOT 별 이상치 도출
A2: LOT | B2: Tag Code | C2: Tag Name | D2: Data Count | E2: 평균 | F2: 표준편차 | G2: 검증기준 | H2: 상한 | I2: 하한 | K2: 유의수준 선택: | M2: 1
A3: 1 | B3: P02M07C031 | C3: 105_Silo_PV | D3: ='01 정보1'!B87 -> 86 | E3: =AVERAGE('01 정보1'!D2:D87) -> 44.610465 | F3: =_xlfn.STDEV.P('01 정보1'!D2:D87) -> 0.52118583 | G3: =IF($M$2=$K$7,$L$7,IF($M$2=$K$8,$L$8,IF($M$2=$K$9,$L$9,$L$10))) -> 1.645 | H3: =E3+F3*G3 -> 45.467816 | I3: =E3-F3*G3 -> 43.753114
A4: 1 | B4: P04M01C002 | C4: Main Screw(MOTOR)-LD | D4: ='01 정보1'!B173 -> 86 | E4: =AVERAGE('01 정보1'!D88:D173) -> 49.326744 | F4: =_xlfn.STDEV.P('01 정보1'!D88:D173) -> 0.69573859 | G4: =IF($M$2=$K$7,$L$7,IF($M$2=$K$8,$L$8,IF($M$2=$K$9,$L$9,$L$10))) -> 1.645 | H4: =E4+F4*G4 -> 50.471234 | I4: =E4-F4*G4 -> 48.182254
A5: 1 | B5: P04M01C004 | C5: MAIN-GP-LD | D5: ='01 정보1'!B259 -> 86 | E5: =AVERAGE('01 정보1'!D174:D259) -> 45.230233 | F5: =_xlfn.STDEV.P('01 정보1'!D174:D259) -> 0.76448337 | G5: =IF($M$2=$K$7,$L$7,IF($M$2=$K$8,$L$8,IF($M$2=$K$9,$L$9,$L$10))) -> 1.645 | H5: =E5+F5*G5 -> 46.487808 | I5: =E5-F5*G5 -> 43.972657
A6: 1 | B6: P09M04C002 | C6: CHILL ROLL-LD | D6: ='01 정보1'!B345 -> 86 | E6: =AVERAGE('01 정보1'!D260:D345) -> -5.755814 | F6: =_xlfn.STDEV.P('01 정보1'!D260:D345) -> 1.0349255 | G6: =IF($M$2=$K$7,$L$7,IF($M$2=$K$8,$L$8,IF($M$2=$K$9,$L$9,$L$10))) -> 1.645 | H6: =E6+F6*G6 -> -4.0533615 | I6: =E6-F6*G6 -> -7.4582664 | K6: 선택 | L6: 유의수준
K7: 1 | L7: 1.645 | M7: 0.9
A8: 2 | B8: P02M07C031 | C8: 105_Silo_PV | D8: ='02 정보2'!B65 -> 64 | E8: =AVERAGE('02 정보2'!D2:D65) -> 39.945313 | F8: =_xlfn.STDEV.P('02 정보2'!D2:D65) -> 0.28500531 | G8: =IF($M$2=$K$7,$L$7,IF($M$2=$K$8,$L$8,IF($M$2=$K$9,$L$9,$L$10))) -> 1.645 | H8: =E8+F8*G8 -> 40.414146 | I8: =E8-F8*G8 -> 39.476479 | K8: 2 | L8: 1.96 | M8: 0.95
A9: 2 | B9: P04M01C002 | C9: Main Screw(MOTOR)-LD | D9: ='02 정보2'!B129 -> 64 | E9: =AVERAGE('02 정보2'!D66:D129) -> 49.7125 | F9: =_xlfn.STDEV.P('02 정보2'!D66:D129) -> 0.22810359 | G9: =IF($M$2=$K$7,$L$7,IF($M$2=$K$8,$L$8,IF($M$2=$K$9,$L$9,$L$10))) -> 1.645 | H9: =E9+F9*G9 -> 50.08773 | I9: =E9-F9*G9 -> 49.33727 | K9: 3 | L9: 2.58 | M9: 0.99
A10: 2 | B10: P04M01C004 | C10: MAIN-GP-LD | D10: ='02 정보2'!B193 -> 64 | E10: =AVERAGE('02 정보2'!D130:D193) -> 45.184375 | F10: =_xlfn.STDEV.P('02 정보2'!D130:D193) -> 0.74103364 | G10: =IF($M$2=$K$7,$L$7,IF($M$2=$K$8,$L$8,IF($M$2=$K$9,$L$9,$L$10))) -> 1.645 | H10: =E10+F10*G10 -> 46.403375 | I10: =E10-F10*G10 -> 43.965375 | K10: 4 | L10: 4.5 | M10: 0.999
A11: 2 | B11: P09M04C002 | C11: CHILL ROLL-LD | D11: ='02 정보2'!B257 -> 64 | E11: =AVERAGE('02 정보2'!D194:D257) -> -5.95625 | F11: =_xlfn.STDEV.P('02 정보2'!D194:D257) -> 1.0147159 | G11: =IF($M$2=$K$7,$L$7,IF($M$2=$K$8,$L$8,IF($M$2=$K$9,$L$9,$L$10))) -> 1.645 | H11: =E11+F11*G11 -> -4.2870423 | I11: =E11-F11*G11 -> -7.6254577
A14: 2. 두 LOT의 평균 검정
A15: LOT | B15: Tag Code | C15: Tag Name | D15: Data Count | E15: 평균 | F15: 표준편차 | G15: Z 통계량 | H15: F 통계량 | I15: 검증(Z, F) | K15: Z 검정 유의수준 선택 | M15: 1 | N15: =IF(M15=K17, L17, IF(M15=K18, L18, L19)) -> 1.645
A16: 1 | B16: P02M07C031 | C16: 105_Silo_PV | D16: =D3 -> 86 | E16: =E3 -> 44.610465 | F16: =F3 -> 0.52118583 | G16: =ABS((E16-E17)/SQRT(ABS((F16^2/D16)+(F17^2/D17)))) -> 70.109241 | H16: =IF(F16>F17, F16^2/F17^2, F17^2/F16^2) -> 3.3441003 | I16: =IF(G16<N15, "OK", "NG") -> NG | K16: 선택 | L16: 유의수준
A17: 2 | B17: P02M07C031 | C17: 105_Silo_PV | D17: =D8 -> 64 | E17: =E8 -> 39.945313 | F17: =F8 -> 0.28500531 | I17: =IF(H16<N22, "OK", "NG") -> NG | K17: 1 | L17: 1.645 | M17: 0.9
K18: 2 | L18: 1.96 | M18: 0.95
A19: 1 | B19: P04M01C002 | C19: Main Screw(MOTOR)-LD | D19: =D4 -> 86 | E19: =E4 -> 49.326744 | F19: =F4 -> 0.69573859 | G19: =ABS((E19-E20)/SQRT(ABS((F19^2/D19)+(F20^2/D20)))) -> 4.8063888 | H19: =IF(F19>F20, F19^2/F20^2, F20^2/F19^2) -> 9.3031052 | I19: =IF(G19<N15,"OK","NG") -> NG | K19: 3 | L19: 2.58 | M19: 0.99
A20: 2 | B20: P04M01C002 | C20: Main Screw(MOTOR)-LD | D20: =D9 -> 64 | E20: =E9 -> 49.7125 | F20: =F9 -> 0.22810359 | I20: =IF(H19<N22, "OK", "NG") -> NG
A22: 1 | B22: P04M01C004 | C22: MAIN-GP-LD | D22: =D5 -> 86 | E22: =E5 -> 45.230233 | F22: =F5 -> 0.76448337 | G22: =ABS((E22-E23)/SQRT(ABS((F22^2/D22)+(F23^2/D23)))) -> 0.36981994 | H22: =IF(F22>F23, F22^2/F23^2, F23^2/F22^2) -> 1.0642906 | I22: =IF(G22<N15, "OK", "NG") -> OK | K22: F 검정 유의수준 선택 | M22: 1 | N22: =IF(M22=K24, L24, IF(M22=K25, L25, L26)) -> 1.26
A23: 2 | B23: P04M01C004 | C23: MAIN-GP-LD | D23: =D10 -> 64 | E23: =E10 -> 45.184375 | F23: =F10 -> 0.74103364 | I23: =IF(H22<N22, "OK", "NG") -> OK | K23: 선택 | L23: 유의수준
K24: 1 | L24: 1.26 | M24: 0.9
A25: 1 | B25: P09M04C002 | C25: CHILL ROLL-LD | D25: =D6 -> 86 | E25: =E6 -> -5.755814 | F25: =F6 -> 1.0349255 | G25: =ABS((E25-E26)/SQRT(ABS((F25^2/D25)+(F26^2/D26)))) -> 1.186395 | H25: =IF(F25>F26, F25^2/F26^2, F26^2/F25^2) -> 1.0402297 | I25: =IF(G25<N15, "OK", "NG") -> OK | K25: 2 | L25: 1.35 | M25: 0.95
A26: 2 | B26: P09M04C002 | C26: CHILL ROLL-LD | D26: =D11 -> 64 | E26: =E11 -> -5.95625 | F26: =F11 -> 1.0147159 | I26: =IF(H25<N22, "OK", "NG") -> OK | K26: 3 | L26: 1.53 | M26: 0.99
B33: TAG_CD | C33: TAG_NAME | D33: AVG_A | E33: SIGMA_A | F33: AVG_B | G33: SIGMA_B | H33: Z_TEST | I33: F_TEST | J33: UNIT
B34: P02M07C031P0 | C34: 105_Silo_PV | D34: 44.61 | E34: 0.52 | F34: 39.95 | G34: 0.29 | H34: 106.849 | I34: 3.331 | J34: TON
B35: P04M01C002P0 | C35: MAIN-Screw(Motor)-LD | D35: 49.33 | E35: 0.7 | F35: 49.71 | G35: 0.23 | H35: 5.528 | I35: 9.265 | J35: %
B36: P09M04C002P0 | C36: CHILL ROLL LD | D36: -5.76 | E36: 1.04 | F36: -5.96 | G36: 1.02 | H36: 3.276 | I36: 1.036 | J36: %
B40: TAG_CD | C40: TAG_NAME | D40: STDDEV_VAL | E40: ROUNDED_SIGMA | F40: STD_DEV | G40: DIFF_SIGMA | H40: AVG_VAL | I40: ROUNDED_AVG | J40: AVG | K40: DIFF_AVG
B41: P02M07C031P0 | C41: 105_Silo_PV | D41: 0.52424266 | E41: 0.52424 | F41: 0.52424 | G41: 0 | H41: 44.610465 | I41: 44.61047 | J41: 44.61047 | K41: 0
B42: P04M01C002P0 | C42: MAIN-Screw(Motor)-LD | D42: 0.69981921 | E42: 0.69982 | F42: 0.69982 | G42: 0 | H42: 49.326744 | I42: 49.32674 | J42: 49.32674 | K42: 0
B43: P04M01C004P0 | C43: MAIN-GP-LD | D43: 0.76896719 | E43: 0.76897 | F43: 0.76897 | G43: 0 | H43: 45.230233 | I43: 45.23023 | J43: 45.23023 | K43: 0
B44: P09M04C002P0 | C44: CHILL ROLL LD | D44: 1.0409955 | E44: 1.041 | F44: 1.041 | G44: 0 | H44: -5.755814 | I44: -5.75581 | J44: -5.75581 | K44: 0
B48: TAG_CD | C48: TAG_NAME | D48: STDDEV_VAL | E48: ROUNDED_SIGMA | F48: STD_DEV | G48: DIFF_SIGMA | H48: AVG_VAL | I48: ROUNDED_AVG | J48: AVG | K48: DIFF_AVG
B49: P02M07C031P0 | C49: 105_Silo_PV | D49: 0.28725835 | E49: 0.28726 | F49: 0.28726 | G49: 0 | H49: 39.945312 | I49: 39.94531 | J49: 39.94531 | K49: 0
B50: P04M01C002P0 | C50: MAIN-Screw(Motor)-LD | D50: 0.22990681 | E50: 0.22991 | F50: 0.22991 | G50: 0 | H50: 49.7125 | I50: 49.7125 | J50: 49.7125 | K50: 0
B51: P04M01C004P0 | C51: MAIN-GP-LD | D51: 0.74689171 | E51: 0.74689 | F51: 0.74689 | G51: 0 | H51: 45.184375 | I51: 45.18438 | J51: 45.18438 | K51: 0
B52: P09M04C002P0 | C52: CHILL ROLL LD | D52: 1.0227375 | E52: 1.02274 | F52: 1.02274 | G52: 0 | H52: -5.95625 | I52: -5.95625 | J52: -5.95625 | K52: 0

Sheet (검증2)개별 Trend Chart
A1: LOT 1 | F1: LOT 2
A2: Tag Code | B2: P04M01C002P0 | D2: P02M07C031P0 | E2: P04M01C002P0 | F2: P04M01C004P0 | G2: P09M04C002P0
A51: Count | B51: Value | C51: 상한값 | D51: 하한값 | F51: Count | G51: Value | H51: 상한값 | I51: 하한값
A52: =IF($B$2=$D$2,'01 정보1'!B2,IF($B$2=$E$2,'01 정보1'!B88,IF($B$2=$F$2,'01 정보1'!B174,IF($B$2=$G$2,'01 정보1'!B260,"Error")))) -> 1 | B52: =IF($B$2=$D$2,'01 정보1'!D2,IF($B$2=$E$2,'01 정보1'!D88,IF($B$2=$F$2,'01 정보1'!D174,IF($B$2=$G$2,'01 정보1'!D260,"Error")))) -> 48.8 | C52: =IF($B$2=$D$2, '(검증1)이상치 검정'!$H$3, IF($B$2=$E$2, '(검증1)이상치 검정'!$H$4, IF($B$2=$F$2, '(검증1)이상치 검정'!$H$5, IF($B$2=$G$2, '(검증1)이상치 검정'!$H$6, "Error")))) -> 50.471234 | D52: =IF($B$2=$D$2, '(검증1)이상치 검정'!$I$3, IF($B$2=$E$2, '(검증1)이상치 검정'!$I$4, IF($B$2=$F$2, '(검증1)이상치 검정'!$I$5, IF($B$2=$G$2, '(검증1)이상치 검정'!$I$6, "Error")))) -> 48.182254 | F52: =IF($B$2=$D$2,'02 정보2'!B2,IF($B$2=$E$2,'02 정보2'!B66,IF($B$2=$F$2,'02 정보2'!B130,IF($B$2=$G$2,'02 정보2'!B194,"Error")))) -> 1 | G52: =IF($B$2=$D$2,'02 정보2'!D2,IF($B$2=$E$2,'02 정보2'!D66,IF($B$2=$F$2,'02 정보2'!D130,IF($B$2=$G$2,'02 정보2'!D194,"Error")))) -> 49.9 | H52: =IF($B$2=$D$2,'(검증1)이상치 검정'!$H$8, IF($B$2=$E$2,'(검증1)이상치 검정'!$H$9, IF($B$2=$F$2,'(검증1)이상치 검정'!$H$10, IF($B$2=$G$2,'(검증1)이상치 검정'!$H$11, "Error")))) -> 50.08773 | I52: =IF($B$2=$D$2,'(검증1)이상치 검정'!$I$8, IF($B$2=$E$2,'(검증1)이상치 검정'!$I$9, IF($B$2=$F$2,'(검증1)이상치 검정'!$I$10, IF($B$2=$G$2,'(검증1)이상치 검정'!$I$11, "Error")))) -> 49.33727
A53: =IF($B$2=$D$2,'01 정보1'!B3,IF($B$2=$E$2,'01 정보1'!B89,IF($B$2=$F$2,'01 정보1'!B175,IF($B$2=$G$2,'01 정보1'!B261,"Error")))) -> 2 | B53: =IF($B$2=$D$2,'01 정보1'!D3,IF($B$2=$E$2,'01 정보1'!D89,IF($B$2=$F$2,'01 정보1'!D175,IF($B$2=$G$2,'01 정보1'!D261,"Error")))) -> 48.7 | C53: =IF($B$2=$D$2, '(검증1)이상치 검정'!$H$3, IF($B$2=$E$2, '(검증1)이상치 검정'!$H$4, IF($B$2=$F$2, '(검증1)이상치 검정'!$H$5, IF($B$2=$G$2, '(검증1)이상치 검정'!$H$6, "Error")))) -> 50.471234 | D53: =IF($B$2=$D$2, '(검증1)이상치 검정'!$I$3, IF($B$2=$E$2, '(검증1)이상치 검정'!$I$4, IF($B$2=$F$2, '(검증1)이상치 검정'!$I$5, IF($B$2=$G$2, '(검증1)이상치 검정'!$I$6, "Error")))) -> 48.182254 | F53: =IF($B$2=$D$2,'02 정보2'!B3,IF($B$2=$E$2,'02 정보2'!B67,IF($B$2=$F$2,'02 정보2'!B131,IF($B$2=$G$2,'02 정보2'!B195,"Error")))) -> 2 | G53: =IF($B$2=$D$2,'02 정보2'!D3,IF($B$2=$E$2,'02 정보2'!D67,IF($B$2=$F$2,'02 정보2'!D131,IF($B$2=$G$2,'02 정보2'!D195,"Error")))) -> 49.7 | H53: =IF($B$2=$D$2,'(검증1)이상치 검정'!$H$8, IF($B$2=$E$2,'(검증1)이상치 검정'!$H$9, IF($B$2=$F$2,'(검증1)이상치 검정'!$H$10, IF($B$2=$G$2,'(검증1)이상치 검정'!$H$11, "Error")))) -> 50.08773 | I53: =IF($B$2=$D$2,'(검증1)이상치 검정'!$I$8, IF($B$2=$E$2,'(검증1)이상치 검정'!$I$9, IF($B$2=$F$2,'(검증1)이상치 검정'!$I$10, IF($B$2=$G$2,'(검증1)이상치 검정'!$I$11, "Error")))) -> 49.33727
A54: =IF($B$2=$D$2,'01 정보1'!B4,IF($B$2=$E$2,'01 정보1'!B90,IF($B$2=$F$2,'01 정보1'!B176,IF($B$2=$G$2,'01 정보1'!B262,"Error")))) -> 3 | B54: =IF($B$2=$D$2,'01 정보1'!D4,IF($B$2=$E$2,'01 정보1'!D90,IF($B$2=$F$2,'01 정보1'!D176,IF($B$2=$G$2,'01 정보1'!D262,"Error")))) -> 48.7 | C54: =IF($B$2=$D$2, '(검증1)이상치 검정'!$H$3, IF($B$2=$E$2, '(검증1)이상치 검정'!$H$4, IF($B$2=$F$2, '(검증1)이상치 검정'!$H$5, IF($B$2=$G$2, '(검증1)이상치 검정'!$H$6, "Error")))) -> 50.471234 | D54: =IF($B$2=$D$2, '(검증1)이상치 검정'!$I$3, IF($B$2=$E$2, '(검증1)이상치 검정'!$I$4, IF($B$2=$F$2, '(검증1)이상치 검정'!$I$5, IF($B$2=$G$2, '(검증1)이상치 검정'!$I$6, "Error")))) -> 48.182254 | F54: =IF($B$2=$D$2,'02 정보2'!B4,IF($B$2=$E$2,'02 정보2'!B68,IF($B$2=$F$2,'02 정보2'!B132,IF($B$2=$G$2,'02 정보2'!B196,"Error")))) -> 3 | G54: =IF($B$2=$D$2,'02 정보2'!D4,IF($B$2=$E$2,'02 정보2'!D68,IF($B$2=$F$2,'02 정보2'!D132,IF($B$2=$G$2,'02 정보2'!D196,"Error")))) -> 49.8 | H54: =IF($B$2=$D$2,'(검증1)이상치 검정'!$H$8, IF($B$2=$E$2,'(검증1)이상치 검정'!$H$9, IF($B$2=$F$2,'(검증1)이상치 검정'!$H$10, IF($B$2=$G$2,'(검증1)이상치 검정'!$H$11, "Error")))) -> 50.08773 | I54: =IF($B$2=$D$2,'(검증1)이상치 검정'!$I$8, IF($B$2=$E$2,'(검증1)이상치 검정'!$I$9, IF($B$2=$F$2,'(검증1)이상치 검정'!$I$10, IF($B$2=$G$2,'(검증1)이상치 검정'!$I$11, "Error")))) -> 49.33727
A55: =IF($B$2=$D$2,'01 정보1'!B5,IF($B$2=$E$2,'01 정보1'!B91,IF($B$2=$F$2,'01 정보1'!B177,IF($B$2=$G$2,'01 정보1'!B263,"Error")))) -> 4 | B55: =IF($B$2=$D$2,'01 정보1'!D5,IF($B$2=$E$2,'01 정보1'!D91,IF($B$2=$F$2,'01 정보1'!D177,IF($B$2=$G$2,'01 정보1'!D263,"Error")))) -> 48.8 | C55: =IF($B$2=$D$2, '(검증1)이상치 검정'!$H$3, IF($B$2=$E$2, '(검증1)이상치 검정'!$H$4, IF($B$2=$F$2, '(검증1)이상치 검정'!$H$5, IF($B$2=$G$2, '(검증1)이상치 검정'!$H$6, "Error")))) -> 50.471234 | D55: =IF($B$2=$D$2, '(검증1)이상치 검정'!$I$3, IF($B$2=$E$2, '(검증1)이상치 검정'!$I$4, IF($B$2=$F$2, '(검증1)이상치 검정'!$I$5, IF($B$2=$G$2, '(검증1)이상치 검정'!$I$6, "Error")))) -> 48.182254 | F55: =IF($B$2=$D$2,'02 정보2'!B5,IF($B$2=$E$2,'02 정보2'!B69,IF($B$2=$F$2,'02 정보2'!B133,IF($B$2=$G$2,'02 정보2'!B197,"Error")))) -> 4 | G55: =IF($B$2=$D$2,'02 정보2'!D5,IF($B$2=$E$2,'02 정보2'!D69,IF($B$2=$F$2,'02 정보2'!D133,IF($B$2=$G$2,'02 정보2'!D197,"Error")))) -> 49.9 | H55: =IF($B$2=$D$2,'(검증1)이상치 검정'!$H$8, IF($B$2=$E$2,'(검증1)이상치 검정'!$H$9, IF($B$2=$F$2,'(검증1)이상치 검정'!$H$10, IF($B$2=$G$2,'(검증1)이상치 검정'!$H$11, "Error")))) -> 50.08773 | I55: =IF($B$2=$D$2,'(검증1)이상치 검정'!$I$8, IF($B$2=$E$2,'(검증1)이상치 검정'!$I$9, IF($B$2=$F$2,'(검증1)이상치 검정'!$I$10, IF($B$2=$G$2,'(검증1)이상치 검정'!$I$11, "Error")))) -> 49.33727
A56: =IF($B$2=$D$2,'01 정보1'!B6,IF($B$2=$E$2,'01 정보1'!B92,IF($B$2=$F$2,'01 정보1'!B178,IF($B$2=$G$2,'01 정보1'!B264,"Error")))) -> 5 | B56: =IF($B$2=$D$2,'01 정보1'!D6,IF($B$2=$E$2,'01 정보1'!D92,IF($B$2=$F$2,'01 정보1'!D178,IF($B$2=$G$2,'01 정보1'!D264,"Error")))) -> 48.6 | C56: =IF($B$2=$D$2, '(검증1)이상치 검정'!$H$3, IF($B$2=$E$2, '(검증1)이상치 검정'!$H$4, IF($B$2=$F$2, '(검증1)이상치 검정'!$H$5, IF($B$2=$G$2, '(검증1)이상치 검정'!$H$6, "Error")))) -> 50.471234 | D56: =IF($B$2=$D$2, '(검증1)이상치 검정'!$I$3, IF($B$2=$E$2, '(검증1)이상치 검정'!$I$4, IF($B$2=$F$2, '(검증1)이상치 검정'!$I$5, IF($B$2=$G$2, '(검증1)이상치 검정'!$I$6, "Error")))) -> 48.182254 | F56: =IF($B$2=$D$2,'02 정보2'!B6,IF($B$2=$E$2,'02 정보2'!B70,IF($B$2=$F$2,'02 정보2'!B134,IF($B$2=$G$2,'02 정보2'!B198,"Error")))) -> 5 | G56: =IF($B$2=$D$2,'02 정보2'!D6,IF($B$2=$E$2,'02 정보2'!D70,IF($B$2=$F$2,'02 정보2'!D134,IF($B$2=$G$2,'02 정보2'!D198,"Error")))) -> 49.9 | H56: =IF($B$2=$D$2,'(검증1)이상치 검정'!$H$8, IF($B$2=$E$2,'(검증1)이상치 검정'!$H$9, IF($B$2=$F$2,'(검증1)이상치 검정'!$H$10, IF($B$2=$G$2,'(검증1)이상치 검정'!$H$11, "Error")))) -> 50.08773 | I56: =IF($B$2=$D$2,'(검증1)이상치 검정'!$I$8, IF($B$2=$E$2,'(검증1)이상치 검정'!$I$9, IF($B$2=$F$2,'(검증1)이상치 검정'!$I$10, IF($B$2=$G$2,'(검증1)이상치 검정'!$I$11, "Error")))) -> 49.33727
A57: =IF($B$2=$D$2,'01 정보1'!B7,IF($B$2=$E$2,'01 정보1'!B93,IF($B$2=$F$2,'01 정보1'!B179,IF($B$2=$G$2,'01 정보1'!B265,"Error")))) -> 6 | B57: =IF($B$2=$D$2,'01 정보1'!D7,IF($B$2=$E$2,'01 정보1'!D93,IF($B$2=$F$2,'01 정보1'!D179,IF($B$2=$G$2,'01 정보1'!D265,"Error")))) -> 48.6 | C57: =IF($B$2=$D$2, '(검증1)이상치 검정'!$H$3, IF($B$2=$E$2, '(검증1)이상치 검정'!$H$4, IF($B$2=$F$2, '(검증1)이상치 검정'!$H$5, IF($B$2=$G$2, '(검증1)이상치 검정'!$H$6, "Error")))) -> 50.471234 | D57: =IF($B$2=$D$2, '(검증1)이상치 검정'!$I$3, IF($B$2=$E$2, '(검증1)이상치 검정'!$I$4, IF($B$2=$F$2, '(검증1)이상치 검정'!$I$5, IF($B$2=$G$2, '(검증1)이상치 검정'!$I$6, "Error")))) -> 48.182254 | F57: =IF($B$2=$D$2,'02 정보2'!B7,IF($B$2=$E$2,'02 정보2'!B71,IF($B$2=$F$2,'02 정보2'!B135,IF($B$2=$G$2,'02 정보2'!B199,"Error")))) -> 6 | G57: =IF($B$2=$D$2,'02 정보2'!D7,IF($B$2=$E$2,'02 정보2'!D71,IF($B$2=$F$2,'02 정보2'!D135,IF($B$2=$G$2,'02 정보2'!D199,"Error")))) -> 49.8 | H57: =IF($B$2=$D$2,'(검증1)이상치 검정'!$H$8, IF($B$2=$E$2,'(검증1)이상치 검정'!$H$9, IF($B$2=$F$2,'(검증1)이상치 검정'!$H$10, IF($B$2=$G$2,'(검증1)이상치 검정'!$H$11, "Error")))) -> 50.08773 | I57: =IF($B$2=$D$2,'(검증1)이상치 검정'!$I$8, IF($B$2=$E$2,'(검증1)이상치 검정'!$I$9, IF($B$2=$F$2,'(검증1)이상치 검정'!$I$10, IF($B$2=$G$2,'(검증1)이상치 검정'!$I$11, "Error")))) -> 49.33727
A58: =IF($B$2=$D$2,'01 정보1'!B8,IF($B$2=$E$2,'01 정보1'!B94,IF($B$2=$F$2,'01 정보1'!B180,IF($B$2=$G$2,'01 정보1'!B266,"Error")))) -> 7 | B58: =IF($B$2=$D$2,'01 정보1'!D8,IF($B$2=$E$2,'01 정보1'!D94,IF($B$2=$F$2,'01 정보1'!D180,IF($B$2=$G$2,'01 정보1'!D266,"Error")))) -> 48.6 | C58: =IF($B$2=$D$2, '(검증1)이상치 검정'!$H$3, IF($B$2=$E$2, '(검증1)이상치 검정'!$H$4, IF($B$2=$F$2, '(검증1)이상치 검정'!$H$5, IF($B$2=$G$2, '(검증1)이상치 검정'!$H$6, "Error")))) -> 50.471234 | D58: =IF($B$2=$D$2, '(검증1)이상치 검정'!$I$3, IF($B$2=$E$2, '(검증1)이상치 검정'!$I$4, IF($B$2=$F$2, '(검증1)이상치 검정'!$I$5, IF($B$2=$G$2, '(검증1)이상치 검정'!$I$6, "Error")))) -> 48.182254 | F58: =IF($B$2=$D$2,'02 정보2'!B8,IF($B$2=$E$2,'02 정보2'!B72,IF($B$2=$F$2,'02 정보2'!B136,IF($B$2=$G$2,'02 정보2'!B200,"Error")))) -> 7 | G58: =IF($B$2=$D$2,'02 정보2'!D8,IF($B$2=$E$2,'02 정보2'!D72,IF($B$2=$F$2,'02 정보2'!D136,IF($B$2=$G$2,'02 정보2'!D200,"Error")))) -> 50 | H58: =IF($B$2=$D$2,'(검증1)이상치 검정'!$H$8, IF($B$2=$E$2,'(검증1)이상치 검정'!$H$9, IF($B$2=$F$2,'(검증1)이상치 검정'!$H$10, IF($B$2=$G$2,'(검증1)이상치 검정'!$H$11, "Error")))) -> 50.08773 | I58: =IF($B$2=$D$2,'(검증1)이상치 검정'!$I$8, IF($B$2=$E$2,'(검증1)이상치 검정'!$I$9, IF($B$2=$F$2,'(검증1)이상치 검정'!$I$10, IF($B$2=$G$2,'(검증1)이상치 검정'!$I$11, "Error")))) -> 49.33727
A59: =IF($B$2=$D$2,'01 정보1'!B9,IF($B$2=$E$2,'01 정보1'!B95,IF($B$2=$F$2,'01 정보1'!B181,IF($B$2=$G$2,'01 정보1'!B267,"Error")))) -> 8 | B59: =IF($B$2=$D$2,'01 정보1'!D9,IF($B$2=$E$2,'01 정보1'!D95,IF($B$2=$F$2,'01 정보1'!D181,IF($B$2=$G$2,'01 정보1'!D267,"Error")))) -> 48.6 | C59: =IF($B$2=$D$2, '(검증1)이상치 검정'!$H$3, IF($B$2=$E$2, '(검증1)이상치 검정'!$H$4, IF($B$2=$F$2, '(검증1)이상치 검정'!$H$5, IF($B$2=$G$2, '(검증1)이상치 검정'!$H$6, "Error")))) -> 50.471234 | D59: =IF($B$2=$D$2, '(검증1)이상치 검정'!$I$3, IF($B$2=$E$2, '(검증1)이상치 검정'!$I$4, IF($B$2=$F$2, '(검증1)이상치 검정'!$I$5, IF($B$2=$G$2, '(검증1)이상치 검정'!$I$6, "Error")))) -> 48.182254 | F59: =IF($B$2=$D$2,'02 정보2'!B9,IF($B$2=$E$2,'02 정보2'!B73,IF($B$2=$F$2,'02 정보2'!B137,IF($B$2=$G$2,'02 정보2'!B201,"Error")))) -> 8 | G59: =IF($B$2=$D$2,'02 정보2'!D9,IF($B$2=$E$2,'02 정보2'!D73,IF($B$2=$F$2,'02 정보2'!D137,IF($B$2=$G$2,'02 정보2'!D201,"Error")))) -> 49.8 | H59: =IF($B$2=$D$2,'(검증1)이상치 검정'!$H$8, IF($B$2=$E$2,'(검증1)이상치 검정'!$H$9, IF($B$2=$F$2,'(검증1)이상치 검정'!$H$10, IF($B$2=$G$2,'(검증1)이상치 검정'!$H$11, "Error")))) -> 50.08773 | I59: =IF($B$2=$D$2,'(검증1)이상치 검정'!$I$8, IF($B$2=$E$2,'(검증1)이상치 검정'!$I$9, IF($B$2=$F$2,'(검증1)이상치 검정'!$I$10, IF($B$2=$G$2,'(검증1)이상치 검정'!$I$11, "Error")))) -> 49.33727
A60: =IF($B$2=$D$2,'01 정보1'!B10,IF($B$2=$E$2,'01 정보1'!B96,IF($B$2=$F$2,'01 정보1'!B182,IF($B$2=$G$2,'01 정보1'!B268,"Error")))) -> 9 | B60: =IF($B$2=$D$2,'01 정보1'!D10,IF($B$2=$E$2,'01 정보1'!D96,IF($B$2=$F$2,'01 정보1'!D182,IF($B$2=$G$2,'01 정보1'!D268,"Error")))) -> 48.6 | C60: =IF($B$2=$D$2, '(검증1)이상치 검정'!$H$3, IF($B$2=$E$2, '(검증1)이상치 검정'!$H$4, IF($B$2=$F$2, '(검증1)이상치 검정'!$H$5, IF($B$2=$G$2, '(검증1)이상치 검정'!$H$6, "Error")))) -> 50.471234 | D60: =IF($B$2=$D$2, '(검증1)이상치 검정'!$I$3, IF($B$2=$E$2, '(검증1)이상치 검정'!$I$4, IF($B$2=$F$2, '(검증1)이상치 검정'!$I$5, IF($B$2=$G$2, '(검증1)이상치 검정'!$I$6, "Error")))) -> 48.182254 | F60: =IF($B$2=$D$2,'02 정보2'!B10,IF($B$2=$E$2,'02 정보2'!B74,IF($B$2=$F$2,'02 정보2'!B138,IF($B$2=$G$2,'02 정보2'!B202,"Error")))) -> 9 | G60: =IF($B$2=$D$2,'02 정보2'!D10,IF($B$2=$E$2,'02 정보2'!D74,IF($B$2=$F$2,'02 정보2'!D138,IF($B$2=$G$2,'02 정보2'!D202,"Error")))) -> 49.7 | H60: =IF($B$2=$D$2,'(검증1)이상치 검정'!$H$8, IF($B$2=$E$2,'(검증1)이상치 검정'!$H$9, IF($B$2=$F$2,'(검증1)이상치 검정'!$H$10, IF($B$2=$G$2,'(검증1)이상치 검정'!$H$11, "Error")))) -> 50.08773 | I60: =IF($B$2=$D$2,'(검증1)이상치 검정'!$I$8, IF($B$2=$E$2,'(검증1)이상치 검정'!$I$9, IF($B$2=$F$2,'(검증1)이상치 검정'!$I$10, IF($B$2=$G$2,'(검증1)이상치 검정'!$I$11, "Error")))) -> 49.33727
A61: =IF($B$2=$D$2,'01 정보1'!B11,IF($B$2=$E$2,'01 정보1'!B97,IF($B$2=$F$2,'01 정보1'!B183,IF($B$2=$G$2,'01 정보1'!B269,"Error")))) -> 10 | B61: =IF($B$2=$D$2,'01 정보1'!D11,IF($B$2=$E$2,'01 정보1'!D97,IF($B$2=$F$2,'01 정보1'!D183,IF($B$2=$G$2,'01 정보1'!D269,"Error")))) -> 49 | C61: =IF($B$2=$D$2, '(검증1)이상치 검정'!$H$3, IF($B$2=$E$2, '(검증1)이상치 검정'!$H$4, IF($B$2=$F$2, '(검증1)이상치 검정'!$H$5, IF($B$2=$G$2, '(검증1)이상치 검정'!$H$6, "Error")))) -> 50.471234 | D61: =IF($B$2=$D$2, '(검증1)이상치 검정'!$I$3, IF($B$2=$E$2, '(검증1)이상치 검정'!$I$4, IF($B$2=$F$2, '(검증1)이상치 검정'!$I$5, IF($B$2=$G$2, '(검증1)이상치 검정'!$I$6, "Error")))) -> 48.182254 | F61: =IF($B$2=$D$2,'02 정보2'!B11,IF($B$2=$E$2,'02 정보2'!B75,IF($B$2=$F$2,'02 정보2'!B139,IF($B$2=$G$2,'02 정보2'!B203,"Error")))) -> 10 | G61: =IF($B$2=$D$2,'02 정보2'!D11,IF($B$2=$E$2,'02 정보2'!D75,IF($B$2=$F$2,'02 정보2'!D139,IF($B$2=$G$2,'02 정보2'!D203,"Error")))) -> 49.3 | H61: =IF($B$2=$D$2,'(검증1)이상치 검정'!$H$8, IF($B$2=$E$2,'(검증1)이상치 검정'!$H$9, IF($B$2=$F$2,'(검증1)이상치 검정'!$H$10, IF($B$2=$G$2,'(검증1)이상치 검정'!$H$11, "Error")))) -> 50.08773 | I61: =IF($B$2=$D$2,'(검증1)이상치 검정'!$I$8, IF($B$2=$E$2,'(검증1)이상치 검정'!$I$9, IF($B$2=$F$2,'(검증1)이상치 검정'!$I$10, IF($B$2=$G$2,'(검증1)이상치 검정'!$I$11, "Error")))) -> 49.33727
A62: =IF($B$2=$D$2,'01 정보1'!B12,IF($B$2=$E$2,'01 정보1'!B98,IF($B$2=$F$2,'01 정보1'!B184,IF($B$2=$G$2,'01 정보1'!B270,"Error")))) -> 11 | B62: =IF($B$2=$D$2,'01 정보1'!D12,IF($B$2=$E$2,'01 정보1'!D98,IF($B$2=$F$2,'01 정보1'!D184,IF($B$2=$G$2,'01 정보1'!D270,"Error")))) -> 49 | C62: =IF($B$2=$D$2, '(검증1)이상치 검정'!$H$3, IF($B$2=$E$2, '(검증1)이상치 검정'!$H$4, IF($B$2=$F$2, '(검증1)이상치 검정'!$H$5, IF($B$2=$G$2, '(검증1)이상치 검정'!$H$6, "Error")))) -> 50.471234 | D62: =IF($B$2=$D$2, '(검증1)이상치 검정'!$I$3, IF($B$2=$E$2, '(검증1)이상치 검정'!$I$4, IF($B$2=$F$2, '(검증1)이상치 검정'!$I$5, IF($B$2=$G$2, '(검증1)이상치 검정'!$I$6, "Error")))) -> 48.182254 | F62: =IF($B$2=$D$2,'02 정보2'!B12,IF($B$2=$E$2,'02 정보2'!B76,IF($B$2=$F$2,'02 정보2'!B140,IF($B$2=$G$2,'02 정보2'!B204,"Error")))) -> 11 | G62: =IF($B$2=$D$2,'02 정보2'!D12,IF($B$2=$E$2,'02 정보2'!D76,IF($B$2=$F$2,'02 정보2'!D140,IF($B$2=$G$2,'02 정보2'!D204,"Error")))) -> 49.5 | H62: =IF($B$2=$D$2,'(검증1)이상치 검정'!$H$8, IF($B$2=$E$2,'(검증1)이상치 검정'!$H$9, IF($B$2=$F$2,'(검증1)이상치 검정'!$H$10, IF($B$2=$G$2,'(검증1)이상치 검정'!$H$11, "Error")))) -> 50.08773 | I62: =IF($B$2=$D$2,'(검증1)이상치 검정'!$I$8, IF($B$2=$E$2,'(검증1)이상치 검정'!$I$9, IF($B$2=$F$2,'(검증1)이상치 검정'!$I$10, IF($B$2=$G$2,'(검증1)이상치 검정'!$I$11, "Error")))) -> 49.33727
A63: =IF($B$2=$D$2,'01 정보1'!B13,IF($B$2=$E$2,'01 정보1'!B99,IF($B$2=$F$2,'01 정보1'!B185,IF($B$2=$G$2,'01 정보1'!B271,"Error")))) -> 12 | B63: =IF($B$2=$D$2,'01 정보1'!D13,IF($B$2=$E$2,'01 정보1'!D99,IF($B$2=$F$2,'01 정보1'!D185,IF($B$2=$G$2,'01 정보1'!D271,"Error")))) -> 48.8 | C63: =IF($B$2=$D$2, '(검증1)이상치 검정'!$H$3, IF($B$2=$E$2, '(검증1)이상치 검정'!$H$4, IF($B$2=$F$2, '(검증1)이상치 검정'!$H$5, IF($B$2=$G$2, '(검증1)이상치 검정'!$H$6, "Error")))) -> 50.471234 | D63: =IF($B$2=$D$2, '(검증1)이상치 검정'!$I$3, IF($B$2=$E$2, '(검증1)이상치 검정'!$I$4, IF($B$2=$F$2, '(검증1)이상치 검정'!$I$5, IF($B$2=$G$2, '(검증1)이상치 검정'!$I$6, "Error")))) -> 48.182254 | F63: =IF($B$2=$D$2,'02 정보2'!B13,IF($B$2=$E$2,'02 정보2'!B77,IF($B$2=$F$2,'02 정보2'!B141,IF($B$2=$G$2,'02 정보2'!B205,"Error")))) -> 12 | G63: =IF($B$2=$D$2,'02 정보2'!D13,IF($B$2=$E$2,'02 정보2'!D77,IF($B$2=$F$2,'02 정보2'!D141,IF($B$2=$G$2,'02 정보2'!D205,"Error")))) -> 49.4 | H63: =IF($B$2=$D$2,'(검증1)이상치 검정'!$H$8, IF($B$2=$E$2,'(검증1)이상치 검정'!$H$9, IF($B$2=$F$2,'(검증1)이상치 검정'!$H$10, IF($B$2=$G$2,'(검증1)이상치 검정'!$H$11, "Error")))) -> 50.08773 | I63: =IF($B$2=$D$2,'(검증1)이상치 검정'!$I$8, IF($B$2=$E$2,'(검증1)이상치 검정'!$I$9, IF($B$2=$F$2,'(검증1)이상치 검정'!$I$10, IF($B$2=$G$2,'(검증1)이상치 검정'!$I$11, "Error")))) -> 49.33727
... A115: =IF($B$2=$D$2,'01 정보1'!B65,IF($B$2=$E$2,'01 정보1'!B151,IF($B$2=$F$2,'01 정보1'!B237,IF($B$2=$G$2,'01 정보1'!B323,"Error")))) -> 64 | B115: =IF($B$2=$D$2,'01 정보1'!D65,IF($B$2=$E$2,'01 정보1'!D151,IF($B$2=$F$2,'01 정보1'!D237,IF($B$2=$G$2,'01 정보1'!D323,"Error")))) -> 49.9 | C115: =IF($B$2=$D$2, '(검증1)이상치 검정'!$H$3, IF($B$2=$E$2, '(검증1)이상치 검정'!$H$4, IF($B$2=$F$2, '(검증1)이상치 검정'!$H$5, IF($B$2=$G$2, '(검증1)이상치 검정'!$H$6, "Error")))) -> 50.471234 | D115: =IF($B$2=$D$2, '(검증1)이상치 검정'!$I$3, IF($B$2=$E$2, '(검증1)이상치 검정'!$I$4, IF($B$2=$F$2, '(검증1)이상치 검정'!$I$5, IF($B$2=$G$2, '(검증1)이상치 검정'!$I$6, "Error")))) -> 48.182254 | F115: =IF($B$2=$D$2,'02 정보2'!B65,IF($B$2=$E$2,'02 정보2'!B129,IF($B$2=$F$2,'02 정보2'!B193,IF($B$2=$G$2,'02 정보2'!B257,"Error")))) -> 64 | G115: =IF($B$2=$D$2,'02 정보2'!D65,IF($B$2=$E$2,'02 정보2'!D129,IF($B$2=$F$2,'02 정보2'!D193,IF($B$2=$G$2,'02 정보2'!D257,"Error")))) -> 50.1 | H115: =IF($B$2=$D$2,'(검증1)이상치 검정'!$H$8, IF($B$2=$E$2,'(검증1)이상치 검정'!$H$9, IF($B$2=$F$2,'(검증1)이상치 검정'!$H$10, IF($B$2=$G$2,'(검증1)이상치 검정'!$H$11, "Error")))) -> 50.08773 | I115: =IF($B$2=$D$2,'(검증1)이상치 검정'!$I$8, IF($B$2=$E$2,'(검증1)이상치 검정'!$I$9, IF($B$2=$F$2,'(검증1)이상치 검정'!$I$10, IF($B$2=$G$2,'(검증1)이상치 검정'!$I$11, "Error")))) -> 49.33727
A116: =IF($B$2=$D$2,'01 정보1'!B66,IF($B$2=$E$2,'01 정보1'!B152,IF($B$2=$F$2,'01 정보1'!B238,IF($B$2=$G$2,'01 정보1'!B324,"Error")))) -> 65 | B116: =IF($B$2=$D$2,'01 정보1'!D66,IF($B$2=$E$2,'01 정보1'!D152,IF($B$2=$F$2,'01 정보1'!D238,IF($B$2=$G$2,'01 정보1'!D324,"Error")))) -> 50 | C116: =IF($B$2=$D$2, '(검증1)이상치 검정'!$H$3, IF($B$2=$E$2, '(검증1)이상치 검정'!$H$4, IF($B$2=$F$2, '(검증1)이상치 검정'!$H$5, IF($B$2=$G$2, '(검증1)이상치 검정'!$H$6, "Error")))) -> 50.471234 | D116: =IF($B$2=$D$2, '(검증1)이상치 검정'!$I$3, IF($B$2=$E$2, '(검증1)이상치 검정'!$I$4, IF($B$2=$F$2, '(검증1)이상치 검정'!$I$5, IF($B$2=$G$2, '(검증1)이상치 검정'!$I$6, "Error")))) -> 48.182254
A117: =IF($B$2=$D$2,'01 정보1'!B67,IF($B$2=$E$2,'01 정보1'!B153,IF($B$2=$F$2,'01 정보1'!B239,IF($B$2=$G$2,'01 정보1'!B325,"Error")))) -> 66 | B117: =IF($B$2=$D$2,'01 정보1'!D67,IF($B$2=$E$2,'01 정보1'!D153,IF($B$2=$F$2,'01 정보1'!D239,IF($B$2=$G$2,'01 정보1'!D325,"Error")))) -> 50 | C117: =IF($B$2=$D$2, '(검증1)이상치 검정'!$H$3, IF($B$2=$E$2, '(검증1)이상치 검정'!$H$4, IF($B$2=$F$2, '(검증1)이상치 검정'!$H$5, IF($B$2=$G$2, '(검증1)이상치 검정'!$H$6, "Error")))) -> 50.471234 | D117: =IF($B$2=$D$2, '(검증1)이상치 검정'!$I$3, IF($B$2=$E$2, '(검증1)이상치 검정'!$I$4, IF($B$2=$F$2, '(검증1)이상치 검정'!$I$5, IF($B$2=$G$2, '(검증1)이상치 검정'!$I$6, "Error")))) -> 48.182254
A118: =IF($B$2=$D$2,'01 정보1'!B68,IF($B$2=$E$2,'01 정보1'!B154,IF($B$2=$F$2,'01 정보1'!B240,IF($B$2=$G$2,'01 정보1'!B326,"Error")))) -> 67 | B118: =IF($B$2=$D$2,'01 정보1'!D68,IF($B$2=$E$2,'01 정보1'!D154,IF($B$2=$F$2,'01 정보1'!D240,IF($B$2=$G$2,'01 정보1'!D326,"Error")))) -> 50.3 | C118: =IF($B$2=$D$2, '(검증1)이상치 검정'!$H$3, IF($B$2=$E$2, '(검증1)이상치 검정'!$H$4, IF($B$2=$F$2, '(검증1)이상치 검정'!$H$5, IF($B$2=$G$2, '(검증1)이상치 검정'!$H$6, "Error")))) -> 50.471234 | D118: =IF($B$2=$D$2, '(검증1)이상치 검정'!$I$3, IF($B$2=$E$2, '(검증1)이상치 검정'!$I$4, IF($B$2=$F$2, '(검증1)이상치 검정'!$I$5, IF($B$2=$G$2, '(검증1)이상치 검정'!$I$6, "Error")))) -> 48.182254
A119: =IF($B$2=$D$2,'01 정보1'!B69,IF($B$2=$E$2,'01 정보1'!B155,IF($B$2=$F$2,'01 정보1'!B241,IF($B$2=$G$2,'01 정보1'!B327,"Error")))) -> 68 | B119: =IF($B$2=$D$2,'01 정보1'!D69,IF($B$2=$E$2,'01 정보1'!D155,IF($B$2=$F$2,'01 정보1'!D241,IF($B$2=$G$2,'01 정보1'!D327,"Error")))) -> 50.4 | C119: =IF($B$2=$D$2, '(검증1)이상치 검정'!$H$3, IF($B$2=$E$2, '(검증1)이상치 검정'!$H$4, IF($B$2=$F$2, '(검증1)이상치 검정'!$H$5, IF($B$2=$G$2, '(검증1)이상치 검정'!$H$6, "Error")))) -> 50.471234 | D119: =IF($B$2=$D$2, '(검증1)이상치 검정'!$I$3, IF($B$2=$E$2, '(검증1)이상치 검정'!$I$4, IF($B$2=$F$2, '(검증1)이상치 검정'!$I$5, IF($B$2=$G$2, '(검증1)이상치 검정'!$I$6, "Error")))) -> 48.182254
A120: =IF($B$2=$D$2,'01 정보1'!B70,IF($B$2=$E$2,'01 정보1'!B156,IF($B$2=$F$2,'01 정보1'!B242,IF($B$2=$G$2,'01 정보1'!B328,"Error")))) -> 69 | B120: =IF($B$2=$D$2,'01 정보1'!D70,IF($B$2=$E$2,'01 정보1'!D156,IF($B$2=$F$2,'01 정보1'!D242,IF($B$2=$G$2,'01 정보1'!D328,"Error")))) -> 50.3 | C120: =IF($B$2=$D$2, '(검증1)이상치 검정'!$H$3, IF($B$2=$E$2, '(검증1)이상치 검정'!$H$4, IF($B$2=$F$2, '(검증1)이상치 검정'!$H$5, IF($B$2=$G$2, '(검증1)이상치 검정'!$H$6, "Error")))) -> 50.471234 | D120: =IF($B$2=$D$2, '(검증1)이상치 검정'!$I$3, IF($B$2=$E$2, '(검증1)이상치 검정'!$I$4, IF($B$2=$F$2, '(검증1)이상치 검정'!$I$5, IF($B$2=$G$2, '(검증1)이상치 검정'!$I$6, "Error")))) -> 48.182254
A121: =IF($B$2=$D$2,'01 정보1'!B71,IF($B$2=$E$2,'01 정보1'!B157,IF($B$2=$F$2,'01 정보1'!B243,IF($B$2=$G$2,'01 정보1'!B329,"Error")))) -> 70 | B121: =IF($B$2=$D$2,'01 정보1'!D71,IF($B$2=$E$2,'01 정보1'!D157,IF($B$2=$F$2,'01 정보1'!D243,IF($B$2=$G$2,'01 정보1'!D329,"Error")))) -> 50.3 | C121: =IF($B$2=$D$2, '(검증1)이상치 검정'!$H$3, IF($B$2=$E$2, '(검증1)이상치 검정'!$H$4, IF($B$2=$F$2, '(검증1)이상치 검정'!$H$5, IF($B$2=$G$2, '(검증1)이상치 검정'!$H$6, "Error")))) -> 50.471234 | D121: =IF($B$2=$D$2, '(검증1)이상치 검정'!$I$3, IF($B$2=$E$2, '(검증1)이상치 검정'!$I$4, IF($B$2=$F$2, '(검증1)이상치 검정'!$I$5, IF($B$2=$G$2, '(검증1)이상치 검정'!$I$6, "Error")))) -> 48.182254
A122: =IF($B$2=$D$2,'01 정보1'!B72,IF($B$2=$E$2,'01 정보1'!B158,IF($B$2=$F$2,'01 정보1'!B244,IF($B$2=$G$2,'01 정보1'!B330,"Error")))) -> 71 | B122: =IF($B$2=$D$2,'01 정보1'!D72,IF($B$2=$E$2,'01 정보1'!D158,IF($B$2=$F$2,'01 정보1'!D244,IF($B$2=$G$2,'01 정보1'!D330,"Error")))) -> 50.3 | C122: =IF($B$2=$D$2, '(검증1)이상치 검정'!$H$3, IF($B$2=$E$2, '(검증1)이상치 검정'!$H$4, IF($B$2=$F$2, '(검증1)이상치 검정'!$H$5, IF($B$2=$G$2, '(검증1)이상치 검정'!$H$6, "Error")))) -> 50.471234 | D122: =IF($B$2=$D$2, '(검증1)이상치 검정'!$I$3, IF($B$2=$E$2, '(검증1)이상치 검정'!$I$4, IF($B$2=$F$2, '(검증1)이상치 검정'!$I$5, IF($B$2=$G$2, '(검증1)이상치 검정'!$I$6, "Error")))) -> 48.182254
A123: =IF($B$2=$D$2,'01 정보1'!B73,IF($B$2=$E$2,'01 정보1'!B159,IF($B$2=$F$2,'01 정보1'!B245,IF($B$2=$G$2,'01 정보1'!B331,"Error")))) -> 72 | B123: =IF($B$2=$D$2,'01 정보1'!D73,IF($B$2=$E$2,'01 정보1'!D159,IF($B$2=$F$2,'01 정보1'!D245,IF($B$2=$G$2,'01 정보1'!D331,"Error")))) -> 50.4 | C123: =IF($B$2=$D$2, '(검증1)이상치 검정'!$H$3, IF($B$2=$E$2, '(검증1)이상치 검정'!$H$4, IF($B$2=$F$2, '(검증1)이상치 검정'!$H$5, IF($B$2=$G$2, '(검증1)이상치 검정'!$H$6, "Error")))) -> 50.471234 | D123: =IF($B$2=$D$2, '(검증1)이상치 검정'!$I$3, IF($B$2=$E$2, '(검증1)이상치 검정'!$I$4, IF($B$2=$F$2, '(검증1)이상치 검정'!$I$5, IF($B$2=$G$2, '(검증1)이상치 검정'!$I$6, "Error")))) -> 48.182254
A124: =IF($B$2=$D$2,'01 정보1'!B74,IF($B$2=$E$2,'01 정보1'!B160,IF($B$2=$F$2,'01 정보1'!B246,IF($B$2=$G$2,'01 정보1'!B332,"Error")))) -> 73 | B124: =IF($B$2=$D$2,'01 정보1'!D74,IF($B$2=$E$2,'01 정보1'!D160,IF($B$2=$F$2,'01 정보1'!D246,IF($B$2=$G$2,'01 정보1'!D332,"Error")))) -> 50.3 | C124: =IF($B$2=$D$2, '(검증1)이상치 검정'!$H$3, IF($B$2=$E$2, '(검증1)이상치 검정'!$H$4, IF($B$2=$F$2, '(검증1)이상치 검정'!$H$5, IF($B$2=$G$2, '(검증1)이상치 검정'!$H$6, "Error")))) -> 50.471234 | D124: =IF($B$2=$D$2, '(검증1)이상치 검정'!$I$3, IF($B$2=$E$2, '(검증1)이상치 검정'!$I$4, IF($B$2=$F$2, '(검증1)이상치 검정'!$I$5, IF($B$2=$G$2, '(검증1)이상치 검정'!$I$6, "Error")))) -> 48.182254
A125: =IF($B$2=$D$2,'01 정보1'!B75,IF($B$2=$E$2,'01 정보1'!B161,IF($B$2=$F$2,'01 정보1'!B247,IF($B$2=$G$2,'01 정보1'!B333,"Error")))) -> 74 | B125: =IF($B$2=$D$2,'01 정보1'!D75,IF($B$2=$E$2,'01 정보1'!D161,IF($B$2=$F$2,'01 정보1'!D247,IF($B$2=$G$2,'01 정보1'!D333,"Error")))) -> 50.2 | C125: =IF($B$2=$D$2, '(검증1)이상치 검정'!$H$3, IF($B$2=$E$2, '(검증1)이상치 검정'!$H$4, IF($B$2=$F$2, '(검증1)이상치 검정'!$H$5, IF($B$2=$G$2, '(검증1)이상치 검정'!$H$6, "Error")))) -> 50.471234 | D125: =IF($B$2=$D$2, '(검증1)이상치 검정'!$I$3, IF($B$2=$E$2, '(검증1)이상치 검정'!$I$4, IF($B$2=$F$2, '(검증1)이상치 검정'!$I$5, IF($B$2=$G$2, '(검증1)이상치 검정'!$I$6, "Error")))) -> 48.182254
A126: =IF($B$2=$D$2,'01 정보1'!B76,IF($B$2=$E$2,'01 정보1'!B162,IF($B$2=$F$2,'01 정보1'!B248,IF($B$2=$G$2,'01 정보1'!B334,"Error")))) -> 75 | B126: =IF($B$2=$D$2,'01 정보1'!D76,IF($B$2=$E$2,'01 정보1'!D162,IF($B$2=$F$2,'01 정보1'!D248,IF($B$2=$G$2,'01 정보1'!D334,"Error")))) -> 50.3 | C126: =IF($B$2=$D$2, '(검증1)이상치 검정'!$H$3, IF($B$2=$E$2, '(검증1)이상치 검정'!$H$4, IF($B$2=$F$2, '(검증1)이상치 검정'!$H$5, IF($B$2=$G$2, '(검증1)이상치 검정'!$H$6, "Error")))) -> 50.471234 | D126: =IF($B$2=$D$2, '(검증1)이상치 검정'!$I$3, IF($B$2=$E$2, '(검증1)이상치 검정'!$I$4, IF($B$2=$F$2, '(검증1)이상치 검정'!$I$5, IF($B$2=$G$2, '(검증1)이상치 검정'!$I$6, "Error")))) -> 48.182254
A127: =IF($B$2=$D$2,'01 정보1'!B77,IF($B$2=$E$2,'01 정보1'!B163,IF($B$2=$F$2,'01 정보1'!B249,IF($B$2=$G$2,'01 정보1'!B335,"Error")))) -> 76 | B127: =IF($B$2=$D$2,'01 정보1'!D77,IF($B$2=$E$2,'01 정보1'!D163,IF($B$2=$F$2,'01 정보1'!D249,IF($B$2=$G$2,'01 정보1'!D335,"Error")))) -> 50.1 | C127: =IF($B$2=$D$2, '(검증1)이상치 검정'!$H$3, IF($B$2=$E$2, '(검증1)이상치 검정'!$H$4, IF($B$2=$F$2, '(검증1)이상치 검정'!$H$5, IF($B$2=$G$2, '(검증1)이상치 검정'!$H$6, "Error")))) -> 50.471234 | D127: =IF($B$2=$D$2, '(검증1)이상치 검정'!$I$3, IF($B$2=$E$2, '(검증1)이상치 검정'!$I$4, IF($B$2=$F$2, '(검증1)이상치 검정'!$I$5, IF($B$2=$G$2, '(검증1)이상치 검정'!$I$6, "Error")))) -> 48.182254
... A137: =IF($B$2=$D$2,'01 정보1'!B87,IF($B$2=$E$2,'01 정보1'!B173,IF($B$2=$F$2,'01 정보1'!B259,IF($B$2=$G$2,'01 정보1'!B345,"Error")))) -> 86 | B137: =IF($B$2=$D$2,'01 정보1'!D87,IF($B$2=$E$2,'01 정보1'!D173,IF($B$2=$F$2,'01 정보1'!D259,IF($B$2=$G$2,'01 정보1'!D345,"Error")))) -> 50.1 | C137: =IF($B$2=$D$2, '(검증1)이상치 검정'!$H$3, IF($B$2=$E$2, '(검증1)이상치 검정'!$H$4, IF($B$2=$F$2, '(검증1)이상치 검정'!$H$5, IF($B$2=$G$2, '(검증1)이상치 검정'!$H$6, "Error")))) -> 50.471234 | D137: =IF($B$2=$D$2, '(검증1)이상치 검정'!$I$3, IF($B$2=$E$2, '(검증1)이상치 검정'!$I$4, IF($B$2=$F$2, '(검증1)이상치 검정'!$I$5, IF($B$2=$G$2, '(검증1)이상치 검정'!$I$6, "Error")))) -> 48.182254

Sheet 01 정보1
A1: TAG_CD | B1: Count | C1: MEASURE_YMDHIS | D1: VALUE | E1: REG_DATE | G1: 검증대상값 | H1: 검증결과
A2: P02M07C031P0 | B2: 1 | C2: 20210814222225 | D2: 45.1 | E2: 44422.932 | G2: =ABS((D2-'(검증1)이상치 검정'!$E$3)/'(검증1)이상치 검정'!$F$3) -> 0.93927129 | H2: =IF(G2>'(검증1)이상치 검정'!$G$3,"Alert","")
A3: P02M07C031P0 | B3: 2 | C3: 20210814222325 | D3: 45.3 | E3: 44422.933 | G3: =ABS((D3-'(검증1)이상치 검정'!$E$3)/'(검증1)이상치 검정'!$F$3) -> 1.3230116 | H3: =IF(G3>'(검증1)이상치 검정'!$G$3,"Alert","")
A4: P02M07C031P0 | B4: 3 | C4: 20210814222425 | D4: 45.4 | E4: 44422.933 | G4: =ABS((D4-'(검증1)이상치 검정'!$E$3)/'(검증1)이상치 검정'!$F$3) -> 1.5148817 | H4: =IF(G4>'(검증1)이상치 검정'!$G$3,"Alert","")
A5: P02M07C031P0 | B5: 4 | C5: 20210814222525 | D5: 45.3 | E5: 44422.934 | G5: =ABS((D5-'(검증1)이상치 검정'!$E$3)/'(검증1)이상치 검정'!$F$3) -> 1.3230116 | H5: =IF(G5>'(검증1)이상치 검정'!$G$3,"Alert","")
A6: P02M07C031P0 | B6: 5 | C6: 20210814222625 | D6: 45.4 | E6: 44422.935 | G6: =ABS((D6-'(검증1)이상치 검정'!$E$3)/'(검증1)이상치 검정'!$F$3) -> 1.5148817 | H6: =IF(G6>'(검증1)이상치 검정'!$G$3,"Alert","")
A7: P02M07C031P0 | B7: 6 | C7: 20210814222725 | D7: 45.5 | E7: 44422.936 | G7: =ABS((D7-'(검증1)이상치 검정'!$E$3)/'(검증1)이상치 검정'!$F$3) -> 1.7067519 | H7: =IF(G7>'(검증1)이상치 검정'!$G$3,"Alert","") -> Alert
A8: P02M07C031P0 | B8: 7 | C8: 20210814222825 | D8: 45.5 | E8: 44422.936 | G8: =ABS((D8-'(검증1)이상치 검정'!$E$3)/'(검증1)이상치 검정'!$F$3) -> 1.7067519 | H8: =IF(G8>'(검증1)이상치 검정'!$G$3,"Alert","") -> Alert
A9: P02M07C031P0 | B9: 8 | C9: 20210814222925 | D9: 45.5 | E9: 44422.937 | G9: =ABS((D9-'(검증1)이상치 검정'!$E$3)/'(검증1)이상치 검정'!$F$3) -> 1.7067519 | H9: =IF(G9>'(검증1)이상치 검정'!$G$3,"Alert","") -> Alert
A10: P02M07C031P0 | B10: 9 | C10: 20210814223025 | D10: 45.4 | E10: 44422.938 | G10: =ABS((D10-'(검증1)이상치 검정'!$E$3)/'(검증1)이상치 검정'!$F$3) -> 1.5148817 | H10: =IF(G10>'(검증1)이상치 검정'!$G$3,"Alert","")
A11: P02M07C031P0 | B11: 10 | C11: 20210814223125 | D11: 45.4 | E11: 44422.938 | G11: =ABS((D11-'(검증1)이상치 검정'!$E$3)/'(검증1)이상치 검정'!$F$3) -> 1.5148817 | H11: =IF(G11>'(검증1)이상치 검정'!$G$3,"Alert","")
A12: P02M07C031P0 | B12: 11 | C12: 20210814223225 | D12: 45.4 | E12: 44422.939 | G12: =ABS((D12-'(검증1)이상치 검정'!$E$3)/'(검증1)이상치 검정'!$F$3) -> 1.5148817 | H12: =IF(G12>'(검증1)이상치 검정'!$G$3,"Alert","")
A13: P02M07C031P0 | B13: 12 | C13: 20210814223325 | D13: 45.3 | E13: 44422.94 | G13: =ABS((D13-'(검증1)이상치 검정'!$E$3)/'(검증1)이상치 검정'!$F$3) -> 1.3230116 | H13: =IF(G13>'(검증1)이상치 검정'!$G$3,"Alert","")
... A87: P02M07C031P0 | B87: 86 | C87: 20210814234725 | D87: 43.7 | E87: 44422.991 | G87: =ABS((D87-'(검증1)이상치 검정'!$E$3)/'(검증1)이상치 검정'!$F$3) -> 1.7469107 | H87: =IF(G87>'(검증1)이상치 검정'!$G$3,"Alert","") -> Alert
A88: P04M01C002P0 | B88: 1 | C88: 20210814222225 | D88: 48.8 | E88: 44422.932 | G88: =ABS((D88-'(검증1)이상치 검정'!$E$4)/'(검증1)이상치 검정'!$F$4) -> 0.75710071 | H88: =IF(G88>'(검증1)이상치 검정'!$G$4,"Alert","")
A89: P04M01C002P0 | B89: 2 | C89: 20210814222325 | D89: 48.7 | E89: 44422.933 | G89: =ABS((D89-'(검증1)이상치 검정'!$E$4)/'(검증1)이상치 검정'!$F$4) -> 0.90083286 | H89: =IF(G89>'(검증1)이상치 검정'!$G$4,"Alert","")
A90: P04M01C002P0 | B90: 3 | C90: 20210814222425 | D90: 48.7 | E90: 44422.933 | G90: =ABS((D90-'(검증1)이상치 검정'!$E$4)/'(검증1)이상치 검정'!$F$4) -> 0.90083286 | H90: =IF(G90>'(검증1)이상치 검정'!$G$4,"Alert","")
A91: P04M01C002P0 | B91: 4 | C91: 20210814222525 | D91: 48.8 | E91: 44422.934 | G91: =ABS((D91-'(검증1)이상치 검정'!$E$4)/'(검증1)이상치 검정'!$F$4) -> 0.75710071 | H91: =IF(G91>'(검증1)이상치 검정'!$G$4,"Alert","")
A92: P04M01C002P0 | B92: 5 | C92: 20210814222625 | D92: 48.6 | E92: 44422.935 | G92: =ABS((D92-'(검증1)이상치 검정'!$E$4)/'(검증1)이상치 검정'!$F$4) -> 1.044565 | H92: =IF(G92>'(검증1)이상치 검정'!$G$4,"Alert","")
A93: P04M01C002P0 | B93: 6 | C93: 20210814222725 | D93: 48.6 | E93: 44422.936 | G93: =ABS((D93-'(검증1)이상치 검정'!$E$4)/'(검증1)이상치 검정'!$F$4) -> 1.044565 | H93: =IF(G93>'(검증1)이상치 검정'!$G$4,"Alert","")
A94: P04M01C002P0 | B94: 7 | C94: 20210814222825 | D94: 48.6 | E94: 44422.936 | G94: =ABS((D94-'(검증1)이상치 검정'!$E$4)/'(검증1)이상치 검정'!$F$4) -> 1.044565 | H94: =IF(G94>'(검증1)이상치 검정'!$G$4,"Alert","")
A95: P04M01C002P0 | B95: 8 | C95: 20210814222925 | D95: 48.6 | E95: 44422.937 | G95: =ABS((D95-'(검증1)이상치 검정'!$E$4)/'(검증1)이상치 검정'!$F$4) -> 1.044565 | H95: =IF(G95>'(검증1)이상치 검정'!$G$4,"Alert","")
A96: P04M01C002P0 | B96: 9 | C96: 20210814223025 | D96: 48.6 | E96: 44422.938 | G96: =ABS((D96-'(검증1)이상치 검정'!$E$4)/'(검증1)이상치 검정'!$F$4) -> 1.044565 | H96: =IF(G96>'(검증1)이상치 검정'!$G$4,"Alert","")
A97: P04M01C002P0 | B97: 10 | C97: 20210814223125 | D97: 49 | E97: 44422.938 | G97: =ABS((D97-'(검증1)이상치 검정'!$E$4)/'(검증1)이상치 검정'!$F$4) -> 0.46963643 | H97: =IF(G97>'(검증1)이상치 검정'!$G$4,"Alert","")
A98: P04M01C002P0 | B98: 11 | C98: 20210814223225 | D98: 49 | E98: 44422.939 | G98: =ABS((D98-'(검증1)이상치 검정'!$E$4)/'(검증1)이상치 검정'!$F$4) -> 0.46963643 | H98: =IF(G98>'(검증1)이상치 검정'!$G$4,"Alert","")
A99: P04M01C002P0 | B99: 12 | C99: 20210814223325 | D99: 48.8 | E99: 44422.94 | G99: =ABS((D99-'(검증1)이상치 검정'!$E$4)/'(검증1)이상치 검정'!$F$4) -> 0.75710071 | H99: =IF(G99>'(검증1)이상치 검정'!$G$4,"Alert","")
... A173: P04M01C002P0 | B173: 86 | C173: 20210814234725 | D173: 50.1 | E173: 44422.991 | G173: =ABS((D173-'(검증1)이상치 검정'!$E$4)/'(검증1)이상치 검정'!$F$4) -> 1.1114172 | H173: =IF(G173>'(검증1)이상치 검정'!$G$4,"Alert","")
A174: P04M01C004P0 | B174: 1 | C174: 20210814222225 | D174: 45.6 | E174: 44422.932 | G174: =ABS((D174-'(검증1)이상치 검정'!$E$5)/'(검증1)이상치 검정'!$F$5) -> 0.48368278 | H174: =IF(G174>'(검증1)이상치 검정'!$G$5,"Alert","")
A175: P04M01C004P0 | B175: 2 | C175: 20210814222325 | D175: 44 | E175: 44422.933 | G175: =ABS((D175-'(검증1)이상치 검정'!$E$5)/'(검증1)이상치 검정'!$F$5) -> 1.6092339 | H175: =IF(G175>'(검증1)이상치 검정'!$G$5,"Alert","")
A176: P04M01C004P0 | B176: 3 | C176: 20210814222425 | D176: 46 | E176: 44422.933 | G176: =ABS((D176-'(검증1)이상치 검정'!$E$5)/'(검증1)이상치 검정'!$F$5) -> 1.0069119 | H176: =IF(G176>'(검증1)이상치 검정'!$G$5,"Alert","")
A177: P04M01C004P0 | B177: 4 | C177: 20210814222525 | D177: 44.5 | E177: 44422.934 | G177: =ABS((D177-'(검증1)이상치 검정'!$E$5)/'(검증1)이상치 검정'!$F$5) -> 0.95519743 | H177: =IF(G177>'(검증1)이상치 검정'!$G$5,"Alert","")
A178: P04M01C004P0 | B178: 5 | C178: 20210814222625 | D178: 45.5 | E178: 44422.935 | G178: =ABS((D178-'(검증1)이상치 검정'!$E$5)/'(검증1)이상치 검정'!$F$5) -> 0.35287549 | H178: =IF(G178>'(검증1)이상치 검정'!$G$5,"Alert","")
A179: P04M01C004P0 | B179: 6 | C179: 20210814222725 | D179: 45.7 | E179: 44422.936 | G179: =ABS((D179-'(검증1)이상치 검정'!$E$5)/'(검증1)이상치 검정'!$F$5) -> 0.61449007 | H179: =IF(G179>'(검증1)이상치 검정'!$G$5,"Alert","")
A180: P04M01C004P0 | B180: 7 | C180: 20210814222825 | D180: 44 | E180: 44422.936 | G180: =ABS((D180-'(검증1)이상치 검정'!$E$5)/'(검증1)이상치 검정'!$F$5) -> 1.6092339 | H180: =IF(G180>'(검증1)이상치 검정'!$G$5,"Alert","")
A181: P04M01C004P0 | B181: 8 | C181: 20210814222925 | D181: 46.2 | E181: 44422.937 | G181: =ABS((D181-'(검증1)이상치 검정'!$E$5)/'(검증1)이상치 검정'!$F$5) -> 1.2685265 | H181: =IF(G181>'(검증1)이상치 검정'!$G$5,"Alert","")
A182: P04M01C004P0 | B182: 9 | C182: 20210814223025 | D182: 44.8 | E182: 44422.938 | G182: =ABS((D182-'(검증1)이상치 검정'!$E$5)/'(검증1)이상치 검정'!$F$5) -> 0.56277556 | H182: =IF(G182>'(검증1)이상치 검정'!$G$5,"Alert","")
A183: P04M01C004P0 | B183: 10 | C183: 20210814223125 | D183: 45.2 | E183: 44422.938 | G183: =ABS((D183-'(검증1)이상치 검정'!$E$5)/'(검증1)이상치 검정'!$F$5) -> 0.039546391 | H183: =IF(G183>'(검증1)이상치 검정'!$G$5,"Alert","")
A184: P04M01C004P0 | B184: 11 | C184: 20210814223225 | D184: 45.9 | E184: 44422.939 | G184: =ABS((D184-'(검증1)이상치 검정'!$E$5)/'(검증1)이상치 검정'!$F$5) -> 0.87610465 | H184: =IF(G184>'(검증1)이상치 검정'!$G$5,"Alert","")
A185: P04M01C004P0 | B185: 12 | C185: 20210814223325 | D185: 44.1 | E185: 44422.94 | G185: =ABS((D185-'(검증1)이상치 검정'!$E$5)/'(검증1)이상치 검정'!$F$5) -> 1.4784266 | H185: =IF(G185>'(검증1)이상치 검정'!$G$5,"Alert","")
... A259: P04M01C004P0 | B259: 86 | C259: 20210814234725 | D259: 45.5 | E259: 44422.991 | G259: =ABS((D259-'(검증1)이상치 검정'!$E$5)/'(검증1)이상치 검정'!$F$5) -> 0.35287549 | H259: =IF(G259>'(검증1)이상치 검정'!$G$5,"Alert","")
...

Sheet 02 정보2
A1: TAG_CD | B1: Count | C1: MEASURE_YMDHIS | D1: VALUE | E1: REG_DATE | G1: 검증대상값 | H1: 검증결과
A2: P02M07C031P0 | B2: 1 | C2: 20210815040525 | D2: 40.2 | E2: 44423.17 | G2: =ABS((D2-'(검증1)이상치 검정'!$E$8)/'(검증1)이상치 검정'!$F$8) -> 0.8936237 | H2: =IF(G2>'(검증1)이상치 검정'!$G$8,"Alert","")
A3: P02M07C031P0 | B3: 2 | C3: 20210815040625 | D3: 40.2 | E3: 44423.171 | G3: =ABS((D3-'(검증1)이상치 검정'!$E$8)/'(검증1)이상치 검정'!$F$8) -> 0.8936237 | H3: =IF(G3>'(검증1)이상치 검정'!$G$8,"Alert","")
A4: P02M07C031P0 | B4: 3 | C4: 20210815040725 | D4: 40.2 | E4: 44423.172 | G4: =ABS((D4-'(검증1)이상치 검정'!$E$8)/'(검증1)이상치 검정'!$F$8) -> 0.8936237 | H4: =IF(G4>'(검증1)이상치 검정'!$G$8,"Alert","")
A5: P02M07C031P0 | B5: 4 | C5: 20210815040825 | D5: 40.1 | E5: 44423.172 | G5: =ABS((D5-'(검증1)이상치 검정'!$E$8)/'(검증1)이상치 검정'!$F$8) -> 0.54275304 | H5: =IF(G5>'(검증1)이상치 검정'!$G$8,"Alert","")
A6: P02M07C031P0 | B6: 5 | C6: 20210815040925 | D6: 40.1 | E6: 44423.173 | G6: =ABS((D6-'(검증1)이상치 검정'!$E$8)/'(검증1)이상치 검정'!$F$8) -> 0.54275304 | H6: =IF(G6>'(검증1)이상치 검정'!$G$8,"Alert","")
A7: P02M07C031P0 | B7: 6 | C7: 20210815041025 | D7: 40.1 | E7: =AVERAGE('02 정보2'!D17:D65) -> 39.926531 | G7: =ABS((D7-'(검증1)이상치 검정'!$E$8)/'(검증1)이상치 검정'!$F$8) -> 0.54275304 | H7: =IF(G7>'(검증1)이상치 검정'!$G$8,"Alert","")
A8: P02M07C031P0 | B8: 7 | C8: 20210815041125 | D8: 40 | E8: 44423.174 | G8: =ABS((D8-'(검증1)이상치 검정'!$E$8)/'(검증1)이상치 검정'!$F$8) -> 0.19188239 | H8: =IF(G8>'(검증1)이상치 검정'!$G$8,"Alert","")
A9: P02M07C031P0 | B9: 8 | C9: 20210815041225 | D9: 40 | E9: 44423.175 | G9: =ABS((D9-'(검증1)이상치 검정'!$E$8)/'(검증1)이상치 검정'!$F$8) -> 0.19188239 | H9: =IF(G9>'(검증1)이상치 검정'!$G$8,"Alert","")
A10: P02M07C031P0 | B10: 9 | C10: 20210815041325 | D10: 40.1 | E10: 44423.176 | G10: =ABS((D10-'(검증1)이상치 검정'!$E$8)/'(검증1)이상치 검정'!$F$8) -> 0.54275304 | H10: =IF(G10>'(검증1)이상치 검정'!$G$8,"Alert","")
A11: P02M07C031P0 | B11: 10 | C11: 20210815041425 | D11: 39.9 | E11: 44423.176 | G11: =ABS((D11-'(검증1)이상치 검정'!$E$8)/'(검증1)이상치 검정'!$F$8) -> 0.15898827 | H11: =IF(G11>'(검증1)이상치 검정'!$G$8,"Alert","")
A12: P02M07C031P0 | B12: 11 | C12: 20210815041525 | D12: 39.9 | E12: 44423.177 | G12: =ABS((D12-'(검증1)이상치 검정'!$E$8)/'(검증1)이상치 검정'!$F$8) -> 0.15898827 | H12: =IF(G12>'(검증1)이상치 검정'!$G$8,"Alert","")
A13: P02M07C031P0 | B13: 12 | C13: 20210815041625 | D13: 39.9 | E13: 44423.178 | G13: =ABS((D13-'(검증1)이상치 검정'!$E$8)/'(검증1)이상치 검정'!$F$8) -> 0.15898827 | H13: =IF(G13>'(검증1)이상치 검정'!$G$8,"Alert","")
A14: P02M07C031P0 | B14: 13 | C14: 20210815041725 | D14: 39.9 | E14: 44423.179 | G14: =ABS((D14-'(검증1)이상치 검정'!$E$8)/'(검증1)이상치 검정'!$F$8) -> 0.15898827 | H14: =IF(G14>'(검증1)이상치 검정'!$G$8,"Alert","")
A15: P02M07C031P0 | B15: 14 | C15: 20210815041825 | D15: 39.8 | E15: 44423.179 | G15: =ABS((D15-'(검증1)이상치 검정'!$E$8)/'(검증1)이상치 검정'!$F$8) -> 0.50985892 | H15: =IF(G15>'(검증1)이상치 검정'!$G$8,"Alert","")
A16: P02M07C031P0 | B16: 15 | C16: 20210815041925 | D16: 39.7 | E16: 44423.18 | G16: =ABS((D16-'(검증1)이상치 검정'!$E$8)/'(검증1)이상치 검정'!$F$8) -> 0.86072957 | H16: =IF(G16>'(검증1)이상치 검정'!$G$8,"Alert","")
A17: P02M07C031P0 | B17: 16 | C17: 20210815042025 | D17: 39.6 | E17: 44423.181 | G17: =ABS((D17-'(검증1)이상치 검정'!$E$8)/'(검증1)이상치 검정'!$F$8) -> 1.2116002 | H17: =IF(G17>'(검증1)이상치 검정'!$G$8,"Alert","")
A18: P02M07C031P0 | B18: 17 | C18: 20210815042125 | D18: 39.6 | E18: 44423.181 | G18: =ABS((D18-'(검증1)이상치 검정'!$E$8)/'(검증1)이상치 검정'!$F$8) -> 1.2116002 | H18: =IF(G18>'(검증1)이상치 검정'!$G$8,"Alert","")
A19: P02M07C031P0 | B19: 18 | C19: 20210815042225 | D19: 39.6 | E19: 44423.182 | G19: =ABS((D19-'(검증1)이상치 검정'!$E$8)/'(검증1)이상치 검정'!$F$8) -> 1.2116002 | H19: =IF(G19>'(검증1)이상치 검정'!$G$8,"Alert","")
... A65: P02M07C031P0 | B65: 64 | C65: 20210815050825 | D65: 39.9 | E65: 44423.214 | G65: =ABS((D65-'(검증1)이상치 검정'!$E$8)/'(검증1)이상치 검정'!$F$8) -> 0.15898827 | H65: =IF(G65>'(검증1)이상치 검정'!$G$8,"Alert","")
A66: P04M01C002P0 | B66: 1 | C66: 20210815040525 | D66: 49.9 | E66: 44423.17 | G66: =ABS((D66-'(검증1)이상치 검정'!$E$9)/'(검증1)이상치 검정'!$F$9) -> 0.82199494 | H66: =IF(G66>'(검증1)이상치 검정'!$G$9,"Alert","")
A67: P04M01C002P0 | B67: 2 | C67: 20210815040625 | D67: 49.7 | E67: 44423.171 | G67: =ABS((D67-'(검증1)이상치 검정'!$E$9)/'(검증1)이상치 검정'!$F$9) -> 0.054799662 | H67: =IF(G67>'(검증1)이상치 검정'!$G$9,"Alert","")
A68: P04M01C002P0 | B68: 3 | C68: 20210815040725 | D68: 49.8 | E68: 44423.172 | G68: =ABS((D68-'(검증1)이상치 검정'!$E$9)/'(검증1)이상치 검정'!$F$9) -> 0.38359764 | H68: =IF(G68>'(검증1)이상치 검정'!$G$9,"Alert","")
A69: P04M01C002P0 | B69: 4 | C69: 20210815040825 | D69: 49.9 | E69: 44423.172 | G69: =ABS((D69-'(검증1)이상치 검정'!$E$9)/'(검증1)이상치 검정'!$F$9) -> 0.82199494 | H69: =IF(G69>'(검증1)이상치 검정'!$G$9,"Alert","")
A70: P04M01C002P0 | B70: 5 | C70: 20210815040925 | D70: 49.9 | E70: 44423.173 | G70: =ABS((D70-'(검증1)이상치 검정'!$E$9)/'(검증1)이상치 검정'!$F$9) -> 0.82199494 | H70: =IF(G70>'(검증1)이상치 검정'!$G$9,"Alert","")
A71: P04M01C002P0 | B71: 6 | C71: 20210815041025 | D71: 49.8 | E71: 44423.174 | G71: =ABS((D71-'(검증1)이상치 검정'!$E$9)/'(검증1)이상치 검정'!$F$9) -> 0.38359764 | H71: =IF(G71>'(검증1)이상치 검정'!$G$9,"Alert","")
A72: P04M01C002P0 | B72: 7 | C72: 20210815041125 | D72: 50 | E72: 44423.174 | G72: =ABS((D72-'(검증1)이상치 검정'!$E$9)/'(검증1)이상치 검정'!$F$9) -> 1.2603922 | H72: =IF(G72>'(검증1)이상치 검정'!$G$9,"Alert","")
A73: P04M01C002P0 | B73: 8 | C73: 20210815041225 | D73: 49.8 | E73: 44423.175 | G73: =ABS((D73-'(검증1)이상치 검정'!$E$9)/'(검증1)이상치 검정'!$F$9) -> 0.38359764 | H73: =IF(G73>'(검증1)이상치 검정'!$G$9,"Alert","")
A74: P04M01C002P0 | B74: 9 | C74: 20210815041325 | D74: 49.7 | E74: 44423.176 | G74: =ABS((D74-'(검증1)이상치 검정'!$E$9)/'(검증1)이상치 검정'!$F$9) -> 0.054799662 | H74: =IF(G74>'(검증1)이상치 검정'!$G$9,"Alert","")
A75: P04M01C002P0 | B75: 10 | C75: 20210815041425 | D75: 49.3 | E75: 44423.176 | G75: =ABS((D75-'(검증1)이상치 검정'!$E$9)/'(검증1)이상치 검정'!$F$9) -> 1.8083889 | H75: =IF(G75>'(검증1)이상치 검정'!$G$9,"Alert","") -> Alert
A76: P04M01C002P0 | B76: 11 | C76: 20210815041525 | D76: 49.5 | E76: 44423.177 | G76: =ABS((D76-'(검증1)이상치 검정'!$E$9)/'(검증1)이상치 검정'!$F$9) -> 0.93159426 | H76: =IF(G76>'(검증1)이상치 검정'!$G$9,"Alert","")
A77: P04M01C002P0 | B77: 12 | C77: 20210815041625 | D77: 49.4 | E77: 44423.178 | G77: =ABS((D77-'(검증1)이상치 검정'!$E$9)/'(검증1)이상치 검정'!$F$9) -> 1.3699916 | H77: =IF(G77>'(검증1)이상치 검정'!$G$9,"Alert","")
... A129: P04M01C002P0 | B129: 64 | C129: 20210815050825 | D129: 50.1 | E129: 44423.214 | G129: =ABS((D129-'(검증1)이상치 검정'!$E$9)/'(검증1)이상치 검정'!$F$9) -> 1.6987895 | H129: =IF(G129>'(검증1)이상치 검정'!$G$9,"Alert","") -> Alert
A130: P04M01C004P0 | B130: 1 | C130: 20210815040525 | D130: 45.4 | E130: 44423.17 | G130: =ABS((D130-'(검증1)이상치 검정'!$E$10)/'(검증1)이상치 검정'!$F$10) -> 0.29097869 | H130: =IF(G130>'(검증1)이상치 검정'!$G$10,"Alert","")
A131: P04M01C004P0 | B131: 2 | C131: 20210815040625 | D131: 44.6 | E131: 44423.171 | G131: =ABS((D131-'(검증1)이상치 검정'!$E$10)/'(검증1)이상치 검정'!$F$10) -> 0.78859443 | H131: =IF(G131>'(검증1)이상치 검정'!$G$10,"Alert","")
A132: P04M01C004P0 | B132: 3 | C132: 20210815040725 | D132: 46.1 | E132: 44423.172 | G132: =ABS((D132-'(검증1)이상치 검정'!$E$10)/'(검증1)이상치 검정'!$F$10) -> 1.2356052 | H132: =IF(G132>'(검증1)이상치 검정'!$G$10,"Alert","")
A133: P04M01C004P0 | B133: 4 | C133: 20210815040825 | D133: 44.3 | E133: 44423.172 | G133: =ABS((D133-'(검증1)이상치 검정'!$E$10)/'(검증1)이상치 검정'!$F$10) -> 1.1934343 | H133: =IF(G133>'(검증1)이상치 검정'!$G$10,"Alert","")
A134: P04M01C004P0 | B134: 5 | C134: 20210815040925 | D134: 46 | E134: 44423.173 | G134: =ABS((D134-'(검증1)이상치 검정'!$E$10)/'(검증1)이상치 검정'!$F$10) -> 1.1006585 | H134: =IF(G134>'(검증1)이상치 검정'!$G$10,"Alert","")
A135: P04M01C004P0 | B135: 6 | C135: 20210815041025 | D135: 45 | E135: 44423.174 | G135: =ABS((D135-'(검증1)이상치 검정'!$E$10)/'(검증1)이상치 검정'!$F$10) -> 0.24880787 | H135: =IF(G135>'(검증1)이상치 검정'!$G$10,"Alert","")
A136: P04M01C004P0 | B136: 7 | C136: 20210815041125 | D136: 44.5 | E136: 44423.174 | G136: =ABS((D136-'(검증1)이상치 검정'!$E$10)/'(검증1)이상치 검정'!$F$10) -> 0.92354107 | H136: =IF(G136>'(검증1)이상치 검정'!$G$10,"Alert","")
...
